<?xml version="1.0"?>
<robot xmlns:xacro="http://www.ros.org/wiki/xacro">

  <!-- Define the macro for the Agilex Piper arm -->
  <xacro:macro name="agilex_piper_arm" params="prefix parent *origin">

    <!-- Properties for joint limits -->
    <xacro:property name="joint1_lower_limit" value="-2.618" />
    <xacro:property name="joint1_upper_limit" value="2.618" />
    <xacro:property name="joint2_lower_limit" value="0" />
    <xacro:property name="joint2_upper_limit" value="3.14" />
    <xacro:property name="joint3_lower_limit" value="-2.967" />
    <xacro:property name="joint3_upper_limit" value="0" />
    <xacro:property name="joint4_lower_limit" value="-1.745" />
    <xacro:property name="joint4_upper_limit" value="1.745" />
    <xacro:property name="joint5_lower_limit" value="-1.22" />
    <xacro:property name="joint5_upper_limit" value="1.22" />
    <xacro:property name="joint6_lower_limit" value="-2.0944" />
    <xacro:property name="joint6_upper_limit" value="2.0944" />

    <!-- Common properties -->
    <xacro:property name="effort_limit" value="100" />
    <xacro:property name="velocity_limit" value="5" />

    <!-- Joint to attach the arm to parent link -->
    <joint name="${prefix}base_joint" type="fixed">
      <xacro:insert_block name="origin" />
      <parent link="${parent}"/>
      <child link="${prefix}base_link"/>
    </joint>

    <!-- Base Link -->
    <link name="${prefix}base_link">
    <inertial>
            <origin xyz="-0.00473641164191482 2.56829134630247E-05 0.041451518036016" rpy="0 0 0" />
            <mass value="1.02" />
            <inertia ixx="0.00267433" ixy="-0.00000073" ixz="-0.00017389" iyy="0.00282612" iyz="0.0000004" izz="0.00089624" />
    </inertial>
      <visual>
        <origin xyz="0 0 0" rpy="0 0 0" />
        <geometry>
          <mesh filename="package://agilex_piper_arm_description/meshes/base_link.STL" />
        </geometry>
        <material name="">
          <color rgba="0.792156862745098 0.819607843137255 0.933333333333333 1" />
        </material>
      </visual>
      <collision>
        <origin xyz="0 0 0" rpy="0 0 0" />
        <geometry>
          <mesh filename="package://agilex_piper_arm_description/meshes/base_link.STL" />
        </geometry>
      </collision>
    </link>

    <!-- Link 1 -->
    <link name="${prefix}link1">
      <inertial>
              <origin xyz="0.000121504734057468 0.000104632162460536 -0.00438597309559853" rpy="0 0 0" />
              <mass value="0.71" />
              <inertia ixx="0.00048916" ixy="-0.00000036" ixz="-0.00000224" iyy="0.00040472" iyz="-0.00000242" izz="0.00043982" />
      </inertial>
      <visual>
        <origin xyz="0 0 0" rpy="0 0 0" />
        <geometry>
          <mesh filename="package://agilex_piper_arm_description/meshes/link1.STL" />
        </geometry>
        <material name="">
          <color rgba="0.792156862745098 0.819607843137255 0.933333333333333 1" />
        </material>
      </visual>
      <collision>
        <origin xyz="0 0 0" rpy="0 0 0" />
        <geometry>
          <mesh filename="package://agilex_piper_arm_description/meshes/link1.STL" />
        </geometry>
      </collision>
    </link>

    <!-- Joint 1 -->
    <joint name="${prefix}joint1" type="revolute">
      <origin xyz="0 0 0.123" rpy="0 0 0" />
      <parent link="${prefix}base_link" />
      <child link="${prefix}link1" />
      <axis xyz="0 0 1" />
      <limit lower="${joint1_lower_limit}" upper="${joint1_upper_limit}"
             effort="${effort_limit}" velocity="${velocity_limit}" />
    </joint>

    <!-- Link 2 -->
    <link name="${prefix}link2">
      <inertial>
              <origin xyz="0.198666145229743 -0.010926924140076 0.00142121714502687" rpy="0 0 0" />
              <mass value="1.17" />
              <inertia ixx="0.00116918" ixy="-0.00180037" ixz="0.00025146" iyy="0.06785384" iyz="-0.00000455" izz="0.06774489" />
      </inertial>
      <visual>
        <origin xyz="0 0 0" rpy="0 0 0" />
        <geometry>
          <mesh filename="package://agilex_piper_arm_description/meshes/link2.STL" />
        </geometry>
        <material name="">
          <color rgba="0.792156862745098 0.819607843137255 0.933333333333333 1" />
        </material>
      </visual>
      <collision>
        <origin xyz="0 0 0" rpy="0 0 0" />
        <geometry>
          <mesh filename="package://agilex_piper_arm_description/meshes/link2.STL" />
        </geometry>
      </collision>
    </link>

    <!-- Joint 2 -->
    <joint name="${prefix}joint2" type="revolute">
      <origin xyz="0 0 0" rpy="1.5708 -0.1359 -3.1416" />
      <parent link="${prefix}link1" />
      <child link="${prefix}link2" />
      <axis xyz="0 0 1" />
      <limit lower="${joint2_lower_limit}" upper="${joint2_upper_limit}"
             effort="${effort_limit}" velocity="${velocity_limit}" />
    </joint>

    <!-- Link 3 -->
    <link name="${prefix}link3">
      <inertial>
              <origin xyz="-0.0202737662122021 -0.133914995944595 -0.000458682652737356" rpy="0 0 0" />
              <mass value="0.5" />
              <inertia ixx="0.01361711" ixy="0.00165794" ixz="-0.00000048" iyy="0.00045024" iyz="-0.00000045" izz="0.01380322" />
      </inertial>
      <visual>
        <origin xyz="0 0 0" rpy="0 0 0" />
        <geometry>
          <mesh filename="package://agilex_piper_arm_description/meshes/link3.STL" />
        </geometry>
        <material name="">
          <color rgba="0.792156862745098 0.819607843137255 0.933333333333333 1" />
        </material>
      </visual>
      <collision>
        <origin xyz="0 0 0" rpy="0 0 0" />
        <geometry>
          <mesh filename="package://agilex_piper_arm_description/meshes/link3.STL" />
        </geometry>
      </collision>
    </link>

    <!-- Joint 3 -->
    <joint name="${prefix}joint3" type="revolute">
      <origin xyz="0.28503 0 0" rpy="0 0 -1.7939" />
      <parent link="${prefix}link2" />
      <child link="${prefix}link3" />
      <axis xyz="0 0 1" />
      <limit lower="${joint3_lower_limit}" upper="${joint3_upper_limit}"
             effort="${effort_limit}" velocity="${velocity_limit}" />
    </joint>

    <!-- Link 4 -->
    <link name="${prefix}link4">
    <inertial>
            <origin xyz="-9.66635791618542E-05 0.000876064475651083 -0.00496880904640868" rpy="0 0 0" />
            <mass value="0.38" />
            <inertia ixx="0.00018501" ixy="0.00000054" ixz="0.00000120" iyy="0.00018965" iyz="-0.00000841" izz="0.00015484" />
    </inertial>
      <visual>
        <origin xyz="0 0 0" rpy="0 0 0" />
        <geometry>
          <mesh filename="package://agilex_piper_arm_description/meshes/link4.STL" />
        </geometry>
        <material name="">
          <color rgba="0.792156862745098 0.819607843137255 0.933333333333333 1" />
        </material>
      </visual>
      <collision>
        <origin xyz="0 0 0" rpy="0 0 0" />
        <geometry>
          <mesh filename="package://agilex_piper_arm_description/meshes/link4.STL" />
        </geometry>
      </collision>
    </link>

    <!-- Joint 4 -->
    <joint name="${prefix}joint4" type="revolute">
      <origin xyz="-0.021984 -0.25075 0" rpy="1.5708 0 0" />
      <parent link="${prefix}link3" />
      <child link="${prefix}link4" />
      <axis xyz="0 0 1" />
      <limit lower="${joint4_lower_limit}" upper="${joint4_upper_limit}"
             effort="${effort_limit}" velocity="${velocity_limit}" />
    </joint>

    <!-- Link 5 -->
    <link name="${prefix}link5">
    <inertial>
            <origin xyz="-4.10554118924211E-05 -0.0566486692356075 -0.0037205791677906" rpy="0 0 0" />
            <mass value="0.383" />
            <inertia ixx="0.00166169" ixy="0.00000006" ixz="-0.00000007" iyy="0.00018510" iyz="0.00001026" izz="0.00164321" />
    </inertial>
      <visual>
        <origin xyz="0 0 0" rpy="0 0 0" />
        <geometry>
          <mesh filename="package://agilex_piper_arm_description/meshes/link5.STL" />
        </geometry>
        <material name="">
          <color rgba="0.792156862745098 0.819607843137255 0.933333333333333 1" />
        </material>
      </visual>
      <collision>
        <origin xyz="0 0 0" rpy="0 0 0" />
        <geometry>
          <mesh filename="package://agilex_piper_arm_description/meshes/link5.STL" />
        </geometry>
      </collision>
    </link>

    <!-- Joint 5 -->
    <joint name="${prefix}joint5" type="revolute">
      <origin xyz="0 0 0" rpy="-1.5708 0 0" />
      <parent link="${prefix}link4" />
      <child link="${prefix}link5" />
      <axis xyz="0 0 1" />
      <limit lower="${joint5_lower_limit}" upper="${joint5_upper_limit}"
             effort="${effort_limit}" velocity="${velocity_limit}" />
    </joint>

    <!-- Link 6 (End Effector) -->
    <link name="${prefix}link6">
    <inertial>
            <origin xyz="-8.82590762930069E-05 9.0598378529832E-06 -0.002" rpy="0 0 0" />
            <mass value="0.00699089613564366" />
            <inertia ixx="5.73015540542155E-07" ixy="-1.98305403089247E-22" ixz="-7.2791893904596E-23" iyy="5.73015540542155E-07" iyz="-3.4146026640245E-24" izz="1.06738869138926E-06" />
    </inertial>
      <visual>
        <origin xyz="0 0 0" rpy="0 0 0" />
        <geometry>
          <mesh filename="package://agilex_piper_arm_description/meshes/link6.STL" />
        </geometry>
        <material name="">
          <color rgba="0.898039215686275 0.917647058823529 0.929411764705882 1" />
        </material>
      </visual>
      <collision>
        <origin xyz="0 0 0" rpy="0 0 0" />
        <geometry>
          <mesh filename="package://agilex_piper_arm_description/meshes/link6.STL" />
        </geometry>
      </collision>
    </link>

    <!-- Joint 6 -->
    <joint name="${prefix}joint6" type="revolute">
      <origin xyz="8.8259E-05 -0.091 0" rpy="1.5708 0 0" />
      <parent link="${prefix}link5" />
      <child link="${prefix}link6" />
      <axis xyz="0 0 1" />
      <limit lower="${joint6_lower_limit}" upper="${joint6_upper_limit}"
             effort="${effort_limit}" velocity="${velocity_limit}" />
    </joint>

    <!-- Tool0 Link - Standard tool mounting point -->
    <link name="${prefix}tool0">
      <inertial>
        <origin xyz="0 0 0" rpy="0 0 0" />
        <mass value="0.001" />
        <inertia ixx="0.000001" ixy="0" ixz="0"
                 iyy="0.000001" iyz="0" izz="0.000001" />
      </inertial>
    </link>

    <!-- Tool0 Joint -->
    <joint name="${prefix}tool0_joint" type="fixed">
      <origin xyz="0 0 0" rpy="0 0 0" />
      <parent link="${prefix}link6" />
      <child link="${prefix}tool0" />
    </joint>

  </xacro:macro>

</robot>
